---
layout: post
title: Chapter 8장 예외처리
date: 2022-08-27 13:27:00 +0900
category: Java
---
# Chapter 8 예외처리

# 1. 예외처리(exception handling)

## 1.1 프로그램 오류

프로그램이 실행 중 어떤 원인에 의해서 오작동을 하거나 비정상적으로 종료되는 원인을 프로그램 `에러` 또는 `오류`라고 한다.

발생시점에 따라 `컴파일 에러`, `런타임 에러`가 있다.

`컴파일 에러` - 커파일 시에 발생하는 에러

`런타임 에러` - 실행 시에 발생하는 에러

`논리적 에러` - 실행은 되지만, 의도와 다르게 동작하는 것

`에러(error)` - 프로그램 코드에 의해서 수습될 수 없는 심각한 오류

`예외(exception)` - 프로그램 코드에 의해서 수습될 수 있는 다소 미약한 오류

## 1.2 예외 클래스의 계층구조

![img-ch8-1.png](/public/img/posts/java/img-ch8-1.png)

모든 클래스의 조상은 Object 클래스이므로 Exception과 Error클래스는 Object의 자손들이다.

![img-ch8-2.png](/public/img/posts/java/img-ch8-2.png)

모든 예외의 최고 조상은 Exception 클래이스이다

**예외 클래스의 두 그룹**

1. Exception 클래스와 그 자손들
2. RuntimeException 클래스와 그 자손들

RuntimeException 클래스들은 주로 프로그래머의 실수에 의해서 발생될 수 있는 예외들로 자바의 프로그래밍 요소들과 관계가 깊다.

배열의 범위를 벗어남(ArrayIndexOutOfBoundsException)

값이 null인 참조변수의 멤버를 호출(NullPointerException)

클래스간의 형변환을 잘못(ClassCastException)

정수를 0으로 나눔(ArithmeticException)

Exception 클래스들은 주로 외부의 영향으로 발생할 수 있는 것들로서, 프로그램의 사용자들의 동작에 의해서 발생하는 경우가 많다.

존재하지 않는 파일의 이름을 입력(FileNotFoundException)

실수로 클래스의 이름을 잘못 적음(classNotFoundException)

입력한 데이터 형식이 잘못(DataFormatException)

## 1.3 예외처리하기 - try-catch문

`예외처리`란 프로그램 실행 시 발생할 수 있는 예기치 못한 예외의 발생에 대비한 코드를 작성하는 것이다.

예외처리의 목적은 예외의 발생으로 인한 실행 중인 프로그램의 갑작스런 비정상 종료를 막고, 정상적인 실행상태를 유지할 수 있도록 하는 것이다.

**예외처리의**

    `정의` - 프로그램 실행 시 발생할 수 있는 예외에 대비한 코드를 작성하는 것

    `목적` - 프로그램의 비정상 종료를 막고, 정상적인 실행상태를 유지하는 것

발생한 예외를 처리하지 못하면, 프로그램은 비정상적으로 종료되며, 처리되지 못한 예외는 JVM의 예외처리기가 받아서 예외의 원인을 화면에 출력한다.

예외를 처리하기 위해서는 try-actch문을 사용한다.

```java
try{
    // 예외가 발생할 가능성이 있는 문장들을 넣는다.
} catch(Exception e){
    // Exception이 발생했을 경우, 이를 처리하기 위한 문장을 적는다.
} catch(Exception2 e2){
    // Exception2이 발생했을 경우, 이를 처리하기 위한 문장을 적는다.
}
```

## 1.4 try-catch문에서의 흐름

문장의 실행순서

**try블럭 내에서 예외가 발생한 경우**

1. 발생한 예외와 일치하는 catch블럭이 있는지 확인한다.
2. 일치하는 catch블럭을 찾게 되면, 그 catch블럭 내의 문장들을 수행하고 전체 try-catch문을 빠져나가서 그 다음 문장을 계속해서 수행한다. 만일 일치하는 catch블럭을 찾지 못하면, 예외는 처리되지 못한다.

**try블럭 내에서 예외가 발생하지 않은 경우**

1. catch블럭을 거치지 않고 전체 try-catch문을 빠져나가서 수행을 계속한다.

## 1.5 예외의 발생과 catch블럭

catch블럭은 괄호()와 블럭{} 두 부분으로 나눠져 있는데, 괄호()내에는 처리하고자 하는 예외와 같은 타입의 참조변수 하나를 선언해야한다.

예외가 발생하면, 발생한 예외에 해당하는 클래스의 인스턴스가 만들어 진다.

첫 번째 catch블럭부터 차례로 내려가면서 catch블럭의 괄호()내에 선언된 참조변수의 종류와 생성된 예외클래스의 인스턴스에 instanceof연산자를 이용해서 검사하게 되는데, 검사결과가 true인 catch블럭을 만날 때까지 검사는 계속된다.

검사결과가 true인 catch블럭을 찾게 되면 블럭에 있는 문장들을 모두 수행한 후에 try-catch문을 빠져나가고 예외는 처리되지만, 검사결과가 true인 catch블럭이 하나도 없으면 예외는 처리되지 않는다.

### printStackTrace()와 getMessage()

`printStackTrace()` - 예외발생 당시의 호출스택(Call Stack)에 있었던 메서드의 정보와 예외 메시지를 화면에 출력한다.

`getMessage()` - 발생한 예외클래스의 인스턴스에 저장된 메시지를 얻을 수 있다.

### 멀티 catch블럭

`멀티 catch블럭`이란 JDK1.7부터 여러 catch블럭을 `|` 기호를 이용해서, 하나의 catch블럭으로 합칠 수 있게 되었다.

```java
try{

} catch(Exception1 | Exception2 e){

}
```

## 1.6 예외 발생시키기

키워드 throw를 사용해서 프로그래머가 고의로 예외를 발생시킬 수 있다.

1. 연산자 new를 이용해서 발생시키려는 예외 클래스의 객체를 만든 다음
2. 키워드 throw를 이용해서 예외를 발생시킨다.

```java
class ExceptionEx9{
    public static void main(String args[]){
        try{
            throw new Exception("고의");
        } catch (Exception e){
            System.out.println("에러 : " + e.getMessage());
            e.printStackTrace();
        }
    }
}
```

## 1.7 메서드에 예외 선언하기

메서드에 예외를 선언하려면, 메서드의 선언부에 키워드 throw를 사용해서 메서드 내에서 발생할 수 있는 예외를 적어주기만 하면 된다.

예외가 여러 개일 경우에는 쉼표(,)로 구분한다.

```java
void method() throws Exception1, Exception2, ... Exception{
}
```

## 1.8 finally블럭

finally블럭은 예외의 발생여부에 상관없이 실행되어야할 코드를 포함시킬 목적으로 사용된다.

try-catch문의 긑에 선택적으로 덧붙여 사용할 수 있으며, try-catch-finally의 순서로 구성된다.

```java
try{
    // 예외가 발생할 가능성이 있는 문장들을 넣는다.
} catch(Exception e){
    // 예외처리를 위한 문장을 적는다.
} finally{
    // 예외의 발생여부에 관계없이 항상 수행되어야하는 문장들을 넣는다.
    // finally블럭은 try-catch문의 맨 마지막에 위치해야한다.
}
```

예외가 발생한 경우에는 `try → catch → finally`의순으로 실행되고, 예외가 발생하지 않은 경우에는 `try → finally`의 순으로 실행된다.

## 1.9 자동 자원 반환 - try-with-resources문

JDK1.7부터 try-with-resources문이라는 try-catch문의 변형이 새로 추가되었다.

주로 입출력에 사용되는 클래스 중에서는 사용한 후에 곡 닫아 줘야 하는 것들이 있다.

그래야 사용했던 자원이 반환되기 때문이다.

```java
try{
    fis = new FileInputStream("score.dat");
    dis = new DataInputStream(fis);

}catch (IOException ie){
    ie.printStacktrace();
} finally{
    try{
        if(dis != null){
            dis.close();
        }
    } catch(IOException ie){
        ie.printStacktrace();
    }
}
```

finally블럭 안에 try-catch문을 추가해서 close()에서 발생할 수 있는 예외를 처리하도록 변경했는데, 코드가 복잡해져서 별로 보기에 좋지 않다. 더 나쁜 것은 try블럭과 finally블럭에서 모두 예외가 발생하면, try블럭의 예외는 무시된다는 것이다.

```java
// 괄호 ()안에 두 문장 이상 넣을 경우 ';'로 구분한다.
try(FileInputStream fis = new FileInputStream("score.dat");
    DataInputStream dis = new DataInputStream(fis)){

    while(true){
        score = dis.readInt();
        System.out.println(score);
        sum += score;
    }
}catch (EOFException e){
    System.out.println("점수 총합 " + sum);
}catch (IOException ie){
    ie.printStacktrace();
}
```

try-with-resources문의 괄호()안에 객체를 생성하는 문장을 넣으면, 이 객체는 따로 close()를 호출하지 않아도 try블럭을 벗어나는 순간 자동적으로 close()가 호출된다. 그다음에 catch블럭 또는 finally블럭이 수행된다.

## 1.10 사용자정의 예외 만들기

기존의 정의된 예외 클래스 외에 필요에 따라 프로그래머가 새로운 예외 클래스를 정의하여 사용할 수 있다.

```java
class MyException extends Exception{
    // 에러 코드 값을 저장하기 위한 필드를 추가 했다
    private final int ERR_CODE;            // 생성자를 통해 초기화 한다

    MyException(String msg, int errCode){  // 생성자
        super(msg);
        ERR_CODE = errCode;
    }

    MyException(String msg){               // 생성자
        this(msg, 100);                    // ERR_CODE를 100(기본값)으로 초기화
    }

    public int getErrCode(){               // 에러 코드를 얻을 수 있는 메서드도 추가
        return ERR_CODE;                   // 이 메서드는 getMessage()와 함께 사용된다
    }
}
```

## 1.11 예외 되던지기(exception re-throwing)

예외를 처리한 수에 인위적으로 다시 발생시키는 방법을 `예외 되던지기`라고 한다.

먼저 예외가 발생할 가능성이 있는 메서드에서 try-catch문을 사용해서 예외를 처리해주고 catch문에서 필요한 작업을 행한 후에 throw문을 사용해서 예외를 다시 발생시킨다.

다시 발행한 예외는 이 메서드를 호출한 메서드에게 전달되고 호출한 메서드의 try-catch문에서 예외를 또다시 처리한다.

```java
class ExceptionEx17{
    public static void main(String[] args){
        try{
            method1();
        } catch (Exception e){
            System.out.println("main 메서드에서 예외 처리");
        }
    }

    static void method1() throws Exception{
        try{
            throw new Exception();
        } catch (Exception e){
            System.out.println("method1에서 예외 처리");
            throw e;           // 다시 예외를 발생
        }
    }
}
```

## 1.12 연결된 예외(chained exception)

한 예외가 다른 예외를 발생시킬 수도 있다.

예외 A가 예외 B를 발생시켰다면, A를 B의 `원인 예외`라고 한다.

```java
try{
    startInstall();                      // SpaceException 발생
    copyFiles();
}catch (SpaceException e){
    InstallException ie = new InstallException("설치중 예외발생"); // 예외 생성
    ie.initCause(e);     // InstallException의 원인 예외를 SpaceException으로 지정
    throw ie;            // InstallException을 발생
}catch (MemoryException me){
...
```

발생한 예외를 그냥 처리하면 될 텐데, 원인 예외로 등록해서 다시 예외를 발생시키는 이유는 여러가지 예외를 하나의 큰 분류의 예외로 묶어서 다루기 위해서이다.